Workbook

Sheet By Product
A1: Yield Historical (Kg) :
A2: NO | B2: PRODUCT | C2: ORIGIN | D2: BATCH 1 | E2: BATCH 2 | F2: BATCH 3 | G2: BATCH 4 | H2: BATCH 5 | I2: BATCH 6 | J2: BATCH 7 | K2: BATCH 8 | L2: BATCH 9 | M2: BATCH 10 | N2: BATCH 11 | O2: BATCH 12 | P2: BATCH 13 | Q2: BATCH 14 | R2: BATCH 15 | S2: BATCH 16 | T2: BATCH 17 | U2: BATCH 18 | V2: BATCH 19 | W2: BATCH 20 | X2: BATCH 21 | Y2: BATCH 22 | Z2: BATCH 23 | AA2: BATCH 24 | AB2: BATCH 25 | AC2: BATCH 26 | AD2: BATCH 27
A3: 1 | B3: RAJANGAN | C3: KASTURI | D3: ='SPR Batch 1'!E117 -> 3011.9 | J3: ='SPR Batch 7'!E89 -> 251.9 | K3: ='SPR Batch8'!E139 -> 425
A4: =A3+1 -> 2 | B4: RAJANGAN | C4: REMBANG | D4: ='SPR Batch 1'!E262 -> 4850 | P4: ='SPR Batch13'!E97 -> 3122.9 | S4: ='SPR Batch16'!E54 -> 1255.1 | V4: ='SPR Batch19'!E68 -> 1646.4
A5: =A4+1 -> 3 | B5: RAJANGAN | C5: Maesan | E5: ='SPR Batch 2'!D33 -> 285.1
A6: =A5+1 -> 4 | B6: RAJANGAN | C6: Paiton | E6: ='SPR Batch 2'!D61 -> 470.9 | F6: ='SPR Batch 3 '!D79 -> 770.8 | G6: ='SPR Batch 4 '!D82 -> 527.7 | H6: ='SPR Batch 5'!E79 -> 816 | I6: ='SPR Batch6'!E95 -> 894.4 | K6: ='SPR Batch8'!E72 -> 445.7 | M6: ='SPR Batch10'!E51 -> 1186.2 | O6: ='SPR Batch12'!E103 -> 2581.9
A7: =A6+1 -> 5 | B7: RAJANGAN | C7: Ploso | E7: ='SPR Batch 2'!D112 -> 187.2 | F7: ='SPR Batch 3 '!D42 -> 563.3 | N7: ='SPR Batch11'!E103 -> 2561.6
A8: =A7+1 -> 6 | B8: RAJANGAN | C8: Lombok 24 | E8: ='SPR Batch 2'!D92 -> 496.2 | F8: ='SPR Batch 3 '!D123 -> 896.3 | G8: ='SPR Batch 4 '!D51 -> 786.6 | H8: ='SPR Batch 5'!E43 -> 664.8 | K8: ='SPR Batch8'!E47 -> 758.3 | L8: ='SPR Batch9'!E53 -> 1007 | Z8: ='SPR Batch23'!E79 -> 1793.2
A9: =A8+1 -> 7 | B9: RAJANGAN | C9: Madura 25 | E9: ='SPR Batch 2'!D134 -> 511 | G9: ='SPR Batch 4 '!D135 -> 412 | H9: ='SPR Batch 5'!E110 -> 671.6 | K9: ='SPR Batch8'!E96 -> 397.3 | L9: ='SPR Batch9'!K104 -> 607.8 | T9: ='SPR Batch17'!E105 -> 2936.8 | U9: ='SPR Batch18'!E188 -> 6145.5
A10: =A9+1 -> 8 | B10: RAJANGAN | C10: Temanggung | E10: ='SPR Batch 2'!D176 -> 382.5 | F10: ='SPR Batch 3 '!D143 -> 380.5 | G10: ='SPR Batch 4 '!D111 -> 222.6 | I10: ='SPR Batch6'!E113 -> 160 | J10: ='SPR Batch 7'!E143 -> 426.3 | K10: ='SPR Batch8'!E113 -> 204 | L10: ='SPR Batch9'!E75 -> 418 | M10: ='SPR Batch10'!E71 -> 318 | Q10: ='SPR Batch14'!E31 -> 731.6 | R10: ='SPR Batch15'!E32 -> 827 | W10: ='SPR Batch20'!E30 -> 752.3 | Y10: ='SPR Batch22'!E30 -> 737.5
A11: =A10+1 -> 9 | B11: RAJANGAN | C11: Lombok 25 | G11: ='SPR Batch 4 '!D159 -> 334.7 | I11: ='SPR Batch6'!E53 -> 827.2 | J11: ='SPR Batch 7'!E65 -> 1195.4 | X11: ='SPR Batch21'!E61 -> 1642.2
B12: GRAND TOTAL | D12: =SUM(D3:D11) -> 7861.9 | E12: =SUM(E3:E11) -> 2332.9 | F12: =SUM(F3:F11) -> 2610.9 | G12: =SUM(G3:G11) -> 2283.6 | H12: =SUM(H3:H11) -> 2152.4 | I12: =SUM(I3:I11) -> 1881.6 | J12: =SUM(J3:J11) -> 1873.6 | K12: =SUM(K3:K11) -> 2230.3 | ... AD12: =SUM(AD3:AD11) -> 0
A14: Bits Stem Historical (Kg):
A15: NO | B15: PRODUCT | C15: ORIGIN | D15: BATCH 1 | E15: BATCH 2 | F15: BATCH 3 | G15: BATCH 4 | H15: BATCH 5 | I15: BATCH 6 | J15: BATCH 7 | K15: BATCH 8 | L15: BATCH 9 | M15: BATCH 10 | N15: BATCH 11 | O15: BATCH 12 | P15: BATCH 13 | Q15: BATCH 14 | R15: BATCH 15 | S15: BATCH 16 | T15: BATCH 17 | U15: BATCH 18 | V15: BATCH 19 | W15: BATCH 20 | X15: BATCH 21 | Y15: BATCH 22 | Z15: BATCH 23 | AA15: BATCH 24 | AB15: BATCH 25 | AC15: BATCH 26 | AD15: BATCH 27
A16: 1 | B16: RAJANGAN | C16: KASTURI | D16: ='SPR Batch 1'!F117 -> 916.5 | J16: ='SPR Batch 7'!F89 -> 150.5 | K16: ='SPR Batch8'!F139 -> 88.1
A17: =A16+1 -> 2 | B17: RAJANGAN | C17: REMBANG | D17: ='SPR Batch 1'!F262 -> 848.3 | P17: ='SPR Batch13'!F97 -> 309.8 | S17: ='SPR Batch16'!F54 -> 185.7 | V17: ='SPR Batch19'!F68 -> 227.7
A18: =A17+1 -> 3 | B18: RAJANGAN | C18: Maesan | E18: ='SPR Batch 2'!E33 -> 95.2
A19: =A18+1 -> 4 | B19: RAJANGAN | C19: Paiton | E19: ='SPR Batch 2'!E61 -> 251.7 | F19: ='SPR Batch 3 '!E79 -> 357.3 | G19: ='SPR Batch 4 '!E82 -> 251.2 | H19: ='SPR Batch 5'!F79 -> 219 | I19: ='SPR Batch6'!F95 -> 400.4 | K19: ='SPR Batch8'!F72 -> 75.1 | M19: ='SPR Batch10'!F51 -> 228 | O19: ='SPR Batch12'!F103 -> 984.9
A20: =A19+1 -> 5 | B20: RAJANGAN | C20: Ploso | E20: ='SPR Batch 2'!E112 -> 78.4 | F20: ='SPR Batch 3 '!E42 -> 157.8 | N20: ='SPR Batch11'!F103 -> 753.6
A21: =A20+1 -> 6 | B21: RAJANGAN | C21: Lombok 24 | E21: ='SPR Batch 2'!E92 -> 211.4 | F21: ='SPR Batch 3 '!E123 -> 432.7 | G21: ='SPR Batch 4 '!E51 -> 345.3 | H21: ='SPR Batch 5'!F43 -> 306.2 | K21: ='SPR Batch8'!F47 -> 263.6 | L21: ='SPR Batch9'!F53 -> 467.9 | Z21: ='SPR Batch23'!F79 -> 377.6
A22: =A21+1 -> 7 | B22: RAJANGAN | C22: Madura 25 | E22: ='SPR Batch 2'!E134 -> 126.6 | G22: ='SPR Batch 4 '!E135 -> 67.7 | H22: ='SPR Batch 5'!F110 -> 127.7 | K22: ='SPR Batch8'!F96 -> 115.2 | L22: ='SPR Batch9'!L104 -> 169.4 | T22: ='SPR Batch17'!F105 -> 201.9 | U22: ='SPR Batch18'!F188 -> 515.6
A23: =A22+1 -> 8 | B23: RAJANGAN | C23: Temanggung | E23: ='SPR Batch 2'!E176 -> 295.8 | F23: ='SPR Batch 3 '!E143 -> 307.4 | G23: ='SPR Batch 4 '!E111 -> 138.8 | I23: ='SPR Batch6'!F113 -> 134.9 | J23: ='SPR Batch 7'!F143 -> 349.6 | K23: ='SPR Batch8'!F113 -> 188.9 | L23: ='SPR Batch9'!F75 -> 492.9 | M23: ='SPR Batch10'!F71 -> 389 | Q23: ='SPR Batch14'!F31 -> 519.9 | R23: ='SPR Batch15'!F32 -> 561.3 | W23: ='SPR Batch20'!F30 -> 444.2 | Y23: ='SPR Batch22'!F30 -> 475.8
A24: =A23+1 -> 9 | B24: RAJANGAN | C24: Lombok 25 | G24: ='SPR Batch 4 '!E159 -> 144.9 | I24: ='SPR Batch6'!F53 -> 443.4 | J24: ='SPR Batch 7'!F65 -> 600.6 | X24: ='SPR Batch21'!F61 -> 298.9
B25: GRAND TOTAL | D25: =SUM(D16:D24) -> 1764.8 | E25: =SUM(E16:E24) -> 1059.1 | F25: =SUM(F16:F24) -> 1255.2 | G25: =SUM(G16:G24) -> 947.9 | H25: =SUM(H16:H24) -> 652.9 | I25: =SUM(I16:I24) -> 978.7 | J25: =SUM(J16:J24) -> 1100.7 | K25: =SUM(K16:K24) -> 730.9 | ... AD25: =SUM(AD16:AD24) -> 0
A26: Dust Historical (Kg) :
A27: NO | B27: PRODUCT | C27: ORIGIN | D27: BATCH 1 | E27: BATCH 2 | F27: BATCH 3 | G27: BATCH 4 | H27: BATCH 5 | I27: BATCH 6 | J27: BATCH 7 | K27: BATCH 8 | L27: BATCH 9 | M27: BATCH 10 | N27: BATCH 11 | O27: BATCH 12 | P27: BATCH 13 | Q27: BATCH 14 | R27: BATCH 15 | S27: BATCH 16 | T27: BATCH 17 | U27: BATCH 18 | V27: BATCH 19 | W27: BATCH 20 | X27: BATCH 21 | Y27: BATCH 22 | Z27: BATCH 23 | AA27: BATCH 24 | AB27: BATCH 25 | AC27: BATCH 26 | AD27: BATCH 27
A28: 1 | B28: RAJANGAN | C28: KASTURI | D28: ='SPR Batch 1'!G117 -> 54.5 | J28: ='SPR Batch 7'!G89 -> 9.2 | K28: ='SPR Batch8'!G139 -> 6.9
A29: =A28+1 -> 2 | B29: RAJANGAN | C29: REMBANG | D29: ='SPR Batch 1'!G262 -> 133.3 | P29: ='SPR Batch13'!G97 -> 95.2 | S29: ='SPR Batch16'!G54 -> 44.3 | V29: ='SPR Batch19'!G68 -> 59
A30: =A29+1 -> 3 | B30: RAJANGAN | C30: Maesan | E30: ='SPR Batch 2'!F33 -> 6.8
A31: =A30+1 -> 4 | B31: RAJANGAN | C31: Paiton | E31: ='SPR Batch 2'!F61 -> 11.1 | F31: ='SPR Batch 3 '!F79 -> 16.7 | G31: ='SPR Batch 4 '!F82 -> 11.9 | H31: ='SPR Batch 5'!G79 -> 13.5 | I31: ='SPR Batch6'!G95 -> 15.4 | K31: ='SPR Batch8'!G72 -> 7.5 | M31: ='SPR Batch10'!G51 -> 27.9 | O31: ='SPR Batch12'!G103 -> 50.2
A32: =A31+1 -> 5 | B32: RAJANGAN | C32: Ploso | E32: ='SPR Batch 2'!F112 -> 3.4 | F32: ='SPR Batch 3 '!F42 -> 6.5 | N32: ='SPR Batch11'!G103 -> 66
A33: =A32+1 -> 6 | B33: RAJANGAN | C33: Lombok 24 | E33: ='SPR Batch 2'!F92 -> 7.1 | F33: ='SPR Batch 3 '!F123 -> 20 | G33: ='SPR Batch 4 '!F51 -> 12.5 | H33: ='SPR Batch 5'!G43 -> 10.7 | K33: ='SPR Batch8'!G47 -> 15.4 | L33: ='SPR Batch9'!G53 -> 16.4 | Z33: ='SPR Batch23'!G79 -> 29.8
A34: =A33+1 -> 7 | B34: RAJANGAN | C34: Madura 25 | E34: ='SPR Batch 2'!F134 -> 10.8 | G34: ='SPR Batch 4 '!F135 -> 6.6 | H34: ='SPR Batch 5'!G110 -> 13.5 | K34: ='SPR Batch8'!G96 -> 7.9 | L34: ='SPR Batch9'!M104 -> 19.6 | T34: ='SPR Batch17'!G105 -> 60.7 | U34: ='SPR Batch18'!G188 -> 135.1
A35: =A34+1 -> 8 | B35: RAJANGAN | C35: Temanggung | E35: ='SPR Batch 2'!F176 -> 15.8 | F35: ='SPR Batch 3 '!F143 -> 8 | G35: ='SPR Batch 4 '!F111 -> 8.2 | I35: ='SPR Batch6'!G113 -> 6.7 | J35: ='SPR Batch 7'!G143 -> 17.8 | K35: ='SPR Batch8'!G113 -> 9.6 | L35: ='SPR Batch9'!G75 -> 19.6 | M35: ='SPR Batch10'!G71 -> 16.7 | Q35: ='SPR Batch14'!G31 -> 23.9 | R35: ='SPR Batch15'!G32 -> 25.9 | W35: ='SPR Batch20'!G30 -> 17.6 | Y35: ='SPR Batch22'!G30 -> 30.5
A36: =A35+1 -> 9 | B36: RAJANGAN | C36: Lombok 25 | G36: ='SPR Batch 4 '!F159 -> 5.4 | I36: ='SPR Batch6'!G53 -> 17.9 | J36: ='SPR Batch 7'!G65 -> 26.7 | X36: ='SPR Batch21'!G61 -> 23.2
B37: GRAND TOTAL | D37: =SUM(D28:D36) -> 187.8 | E37: =SUM(E28:E36) -> 55 | F37: =SUM(F28:F36) -> 51.2 | G37: =SUM(G28:G36) -> 44.6 | H37: =SUM(H28:H36) -> 37.7 | I37: =SUM(I28:I36) -> 40 | J37: =SUM(J28:J36) -> 53.7 | K37: =SUM(K28:K36) -> 47.3 | ... AD37: =SUM(AD28:AD36) -> 0
A38: Accountable Waste Historical (Kg) :
A39: NO | B39: PRODUCT | C39: ORIGIN | D39: BATCH 1 | E39: BATCH 2 | F39: BATCH 3 | G39: BATCH 4 | H39: BATCH 5 | I39: BATCH 6 | J39: BATCH 7 | K39: BATCH 8 | L39: BATCH 9 | M39: BATCH 10 | N39: BATCH 11 | O39: BATCH 12 | P39: BATCH 13 | Q39: BATCH 14 | R39: BATCH 15 | S39: BATCH 16 | T39: BATCH 17 | U39: BATCH 18 | V39: BATCH 19 | W39: BATCH 20 | X39: BATCH 21 | Y39: BATCH 22 | Z39: BATCH 23 | AA39: BATCH 24 | AB39: BATCH 25 | AC39: BATCH 26 | AD39: BATCH 27
A40: 1 | B40: RAJANGAN | C40: KASTURI | D40: ='SPR Batch 1'!H117 -> 46 | J40: ='SPR Batch 7'!H89 -> 2.9 | K40: ='SPR Batch8'!H139 -> 2.6
A41: =A40+1 -> 2 | B41: RAJANGAN | C41: REMBANG | D41: ='SPR Batch 1'!H262 -> 81.4 | P41: ='SPR Batch13'!H97 -> 16.6 | S41: ='SPR Batch16'!H54 -> 4.1 | V41: ='SPR Batch19'!H68 -> 7.4
...

Sheet AVG
A1: Yield Historical :
A2: NO | B2: PRODUCT | C2: ORIGIN | D2: BATCH 1 | E2: BATCH 2 | F2: BATCH 3 | G2: BATCH 4 | H2: BATCH 5 | I2: BATCH 6 | J2: BATCH 7 | K2: BATCH 8 | L2: BATCH 9 | M2: BATCH 10 | N2: BATCH 11 | O2: BATCH 12 | P2: BATCH 13 | Q2: BATCH 14 | R2: BATCH 15 | S2: BATCH 16 | T2: BATCH 17 | U2: BATCH 18 | V2: BATCH 19 | W2: BATCH 20 | X2: BATCH 21 | Y2: BATCH 22 | Z2: BATCH 23 | AA2: BATCH 24 | AB2: BATCH 25 | AC2: BATCH 26 | AD2: BATCH 27
A3: 1 | B3: RAJANGAN | C3: KASTURI | D3: ='SPR Batch 1'!E118 -> 0.74757378 | J3: ='SPR Batch 7'!E90 -> 0.60772014 | K3: ='SPR Batch8'!E140 -> 0.81324148
A4: =A3+1 -> 2 | B4: RAJANGAN | C4: REMBANG | D4: ='SPR Batch 1'!E263 -> 0.82022662 | P4: ='SPR Batch13'!E98 -> 0.88105516 | S4: ='SPR Batch16'!E55 -> 0.8428015 | V4: ='SPR Batch19'!E69 -> 0.84844112
A5: =A4+1 -> 3 | B5: RAJANGAN | C5: Maesan | E5: ='SPR Batch 2'!D34 -> 0.70325604
A6: =A5+1 -> 4 | B6: RAJANGAN | C6: Paiton | E6: ='SPR Batch 2'!D62 -> 0.63574997 | F6: 0.6662057 | G6: ='SPR Batch 4 '!D83 -> 0.6611125 | H6: ='SPR Batch 5'!E80 -> 0.77002925 | I6: 0.67278471 | K6: ='SPR Batch8'!E73 -> 0.84253308 | M6: ='SPR Batch10'!E52 -> 0.81503367 | O6: ='SPR Batch12'!E104 -> 0.71209112 | AB6: ='SPR Batch25'!E70 -> 0.79695431
A7: =A6+1 -> 5 | B7: RAJANGAN | C7: Ploso | E7: ='SPR Batch 2'!D113 -> 0.67703436 | F7: 0.75967633 | N7: ='SPR Batch11'!E104 -> 0.74990486
A8: =A7+1 -> 6 | B8: RAJANGAN | C8: Lombok 24 | E8: ='SPR Batch 2'!D93 -> 0.68337695 | F8: 0.6498277 | G8: ='SPR Batch 4 '!D52 -> 0.68210198 | H8: ='SPR Batch 5'!E44 -> 0.66968873 | K8: ='SPR Batch8'!E48 -> 0.72177803 | L8: ='SPR Batch9'!E54 -> 0.73546597 | Z8: ='SPR Batch23'!E80 -> 0.81169654 | AB8: ='SPR Batch25'!E113 -> 0.73498965
A9: =A8+1 -> 7 | B9: RAJANGAN | C9: Madura 25 | E9: ='SPR Batch 2'!D135 -> 0.77155368 | G9: ='SPR Batch 4 '!D136 -> 0.83081266 | H9: 0.814258 | K9: ='SPR Batch8'!E97 -> 0.76271837 | L9: ='SPR Batch9'!K123 -> 0.75869062 | T9: ='SPR Batch17'!E106 -> 0.91689042 | U9: ='SPR Batch18'!E189 -> 0.89372191
A10: =A9+1 -> 8 | B10: RAJANGAN | C10: Temanggung | E10: 0.54956897 | F10: 0.54109784 | G10: ='SPR Batch 4 '!D112 -> 0.60032362 | I10: 0.52407468 | J10: ='SPR Batch 7'!E144 -> 0.532875 | K10: ='SPR Batch8'!E114 -> 0.49987748 | L10: ='SPR Batch9'!E76 -> 0.44270282 | M10: ='SPR Batch10'!E72 -> 0.43212393 | Q10: ='SPR Batch14'!E32 -> 0.56664859 | R10: ='SPR Batch15'!E33 -> 0.57582509 | W10: ='SPR Batch20'!E31 -> 0.60939652 | Y10: ='SPR Batch22'!E31 -> 0.58554982
A11: =A10+1 -> 9 | B11: RAJANGAN | C11: Lombok 25 | G11: ='SPR Batch 4 '!D160 -> 0.68278254 | I11: 0.63542787 | J11: ='SPR Batch 7'!E66 -> 0.65451161 | X11: ='SPR Batch21'!E62 -> 0.83335025
A12: =A11+1 -> 10 | B12: RAJANGAN
A13: =A12+1 -> 11 | B13: RAJANGAN
A15: Note :
B16: > 70 %
B17: 65 % - 70 %
B18: < 65 %
A19: Bits Stem Historical :
A20: NO | B20: PRODUCT | C20: ORIGIN | D20: BATCH 1 | E20: BATCH 2 | F20: BATCH 3 | G20: BATCH 4 | H20: BATCH 5 | I20: BATCH 6 | J20: BATCH 7 | K20: BATCH 8 | L20: BATCH 9 | M20: BATCH 10 | N20: BATCH 11 | O20: BATCH 12 | P20: BATCH 13 | Q20: BATCH 14 | R20: BATCH 15 | S20: BATCH 16 | T20: BATCH 17 | U20: BATCH 18 | V20: BATCH 19 | W20: BATCH 20 | X20: BATCH 21 | Y20: BATCH 22 | Z20: BATCH 23 | AA20: BATCH 24 | AB20: BATCH 25 | AC20: BATCH 26 | AD20: BATCH 27
A21: 1 | B21: RAJANGAN | C21: KASTURI | D21: ='SPR Batch 1'!F118 -> 0.22748145 | J21: ='SPR Batch 7'!F90 -> 0.36308806 | K21: ='SPR Batch8'!F140 -> 0.16858018
A22: =A21+1 -> 2 | B22: RAJANGAN | C22: REMBANG | D22: ='SPR Batch 1'!F263 -> 0.14346355 | P22: ='SPR Batch13'!F98 -> 0.087403019 | S22: ='SPR Batch16'!F55 -> 0.12469782 | V22: ='SPR Batch19'!F69 -> 0.11734089
A23: =A22+1 -> 3 | B23: RAJANGAN | C23: Maesan | E23: ='SPR Batch 2'!E34 -> 0.2348298
A24: =A23+1 -> 4 | B24: RAJANGAN | C24: Paiton | E24: ='SPR Batch 2'!E62 -> 0.33981369 | F24: ='SPR Batch 3 '!E80 -> 0.3088159 | G24: ='SPR Batch 4 '!E83 -> 0.31470809 | H24: ='SPR Batch 5'!F80 -> 0.20666226 | I24: ='SPR Batch6'!F96 -> 0.30118851 | K24: ='SPR Batch8'!F73 -> 0.14196597 | M24: ='SPR Batch10'!F52 -> 0.15665796 | O24: ='SPR Batch12'!F104 -> 0.2716366
A25: =A24+1 -> 5 | B25: RAJANGAN | C25: Ploso | E25: ='SPR Batch 2'!E113 -> 0.2835443 | F25: ='SPR Batch 3 '!E43 -> 0.21281187 | N25: ='SPR Batch11'!F104 -> 0.22061536
A26: =A25+1 -> 6 | B26: RAJANGAN | C26: Lombok 24 | E26: ='SPR Batch 2'!E93 -> 0.29114447 | F26: ='SPR Batch 3 '!E124 -> 0.317252 | G26: ='SPR Batch 4 '!E52 -> 0.29942768 | H26: ='SPR Batch 5'!F44 -> 0.3084517 | K26: ='SPR Batch8'!F48 -> 0.25090425 | L26: ='SPR Batch9'!F54 -> 0.3417324 | Z26: ='SPR Batch23'!F80 -> 0.1709216
A27: =A26+1 -> 7 | B27: RAJANGAN | C27: Madura 25 | E27: ='SPR Batch 2'!E135 -> 0.19115205 | G27: ='SPR Batch 4 '!E136 -> 0.13651946 | H27: ='SPR Batch 5'!F111 -> 0.15482541 | K27: ='SPR Batch8'!F97 -> 0.22115569 | L27: ='SPR Batch9'!L123 -> 0.21072924 | T27: ='SPR Batch17'!F106 -> 0.063034655 | U27: ='SPR Batch18'!F189 -> 0.074982185
A28: =A27+1 -> 8 | B28: RAJANGAN | C28: Temanggung | E28: 0.425 | F28: ='SPR Batch 3 '!E144 -> 0.43714448 | G28: ='SPR Batch 4 '!E112 -> 0.37432578 | I28: ='SPR Batch6'!F114 -> 0.44186047 | J28: ='SPR Batch 7'!F144 -> 0.437 | K28: ='SPR Batch8'!F114 -> 0.46287675 | L28: ='SPR Batch9'!F76 -> 0.52202923 | M28: ='SPR Batch10'!F72 -> 0.52860443 | Q28: ='SPR Batch14'!F32 -> 0.40267989 | R28: ='SPR Batch15'!F33 -> 0.39082301 | W28: ='SPR Batch20'!F31 -> 0.35982179 | Y28: ='SPR Batch22'!F31 -> 0.37776896
A29: =A28+1 -> 9 | B29: RAJANGAN | C29: Lombok 25 | G29: ='SPR Batch 4 '!E160 -> 0.29559364 | I29: ='SPR Batch6'!F54 -> 0.34060532 | J29: ='SPR Batch 7'!F66 -> 0.32884363 | X29: ='SPR Batch21'!F62 -> 0.15167969
A30: Note :
B31: <27%
B32: 27 % - 30 %
B33: > 30 %
A34: Dust Historical :
A35: NO | B35: PRODUCT | C35: ORIGIN | D35: BATCH 1 | E35: BATCH 2 | F35: BATCH 3 | G35: BATCH 4 | H35: BATCH 5 | I35: BATCH 6 | J35: BATCH 7 | K35: BATCH 8 | L35: BATCH 9 | M35: BATCH 10 | N35: BATCH 11 | O35: BATCH 12 | P35: BATCH 13 | Q35: BATCH 14 | R35: BATCH 15 | S35: BATCH 16 | T35: BATCH 17 | U35: BATCH 18 | V35: BATCH 19 | W35: BATCH 20 | X35: BATCH 21 | Y35: BATCH 22 | Z35: BATCH 23 | AA35: BATCH 24 | AB35: BATCH 25 | AC35: BATCH 26 | AD35: BATCH 27
A36: 1 | B36: RAJANGAN | C36: KASTURI | D36: ='SPR Batch 1'!G118 -> 0.013527266 | J36: ='SPR Batch 7'!G90 -> 0.022195416 | K36: ='SPR Batch8'!G140 -> 0.013203215
A37: =A36+1 -> 2 | B37: RAJANGAN | C37: REMBANG | D37: ='SPR Batch 1'!G263 -> 0.022543548 | P37: ='SPR Batch13'!G98 -> 0.026858513 | S37: ='SPR Batch16'!G55 -> 0.029747515 | V37: ='SPR Batch19'!G69 -> 0.030404535
A38: =A37+1 -> 3 | B38: RAJANGAN | C38: Maesan | E38: ='SPR Batch 2'!F34 -> 0.016773557
A39: =A38+1 -> 4 | B39: RAJANGAN | C39: Paiton | E39: ='SPR Batch 2'!F62 -> 0.014985824 | F39: ='SPR Batch 3 '!F80 -> 0.014433881 | G39: ='SPR Batch 4 '!F83 -> 0.014908544 | H39: ='SPR Batch 5'!G80 -> 0.012739455 | I39: ='SPR Batch6'!G96 -> 0.011584173 | K39: ='SPR Batch8'!G73 -> 0.014177694 | M39: ='SPR Batch10'!G52 -> 0.019169988 | O39: ='SPR Batch12'!G104 -> 0.01384522
A40: =A39+1 -> 5 | B40: RAJANGAN | C40: Ploso | E40: ='SPR Batch 2'!F113 -> 0.012296564 | F40: ='SPR Batch 3 '!F43 -> 0.0087660148 | N40: ='SPR Batch11'!G104 -> 0.019321409
A41: =A40+1 -> 6 | B41: RAJANGAN | C41: Lombok 24 | E41: ='SPR Batch 2'!F93 -> 0.0097782675 | F41: ='SPR Batch 3 '!F124 -> 0.014663832 | G41: ='SPR Batch 4 '!F52 -> 0.010839403 | H41: ='SPR Batch 5'!G44 -> 0.010778684 | K41: ='SPR Batch8'!G48 -> 0.014658291 | L41: ='SPR Batch9'!G54 -> 0.011977797 | Z41: ='SPR Batch23'!G80 -> 0.013489046
...

Sheet SPR Batch 1
A1: PROCESS CERTIFICATE
A3: DELIVERY NOTE :
A4: Customer | B4: : Bpk. Bimo (PT. Falih Nur Gemilang) | H4: Issued Date : | I4: 46190
A6: Product Type | B6: Origin | C6: Total Pack (Unit) | D6: Pack Type | E6: Gross (Kg) | F6: Tare (Kg) | G6: Netto ( Kg) | H6: Date of Receipt | I6: Delivery Note Number
A7: RAJANGAN | B7: KASTURI | C7: 96 | D7: Ball Goni | E7: 4156.4 | F7: 127.5 | G7: =E7-F7 -> 4028.9 | H7: 46177 | I7: - | K7: 4156.4 | L7: 96 | M7: 60 | N7: 36
A8: RAJANGAN | B8: REMBANG | C8: 127 | D8: Ball Goni | E8: 6066.4 | F8: 153.4 | G8: =E8-F8 -> 5913 | H8: 46177 | I8: - | K8: 5752.6 | L8: 127 | M8: 131
A10: Remark :
A11: 1. Gross Qty. Based on Delivery Note.
A12: 2. Tare Qty. Based on actual weighing during the process.
A14: SEPARATION RESULTS REPORT :
A15: 1. Material Desc. | B15: : KASTURI
A16: Product Type | B16: Origin | C16: Pack Type | E16: No | F16: Gross (Kg) | G16: Tare (Kg) | H16: Netto ( Kg) | I16: Remark
A17: RAJANGAN | B17: KASTURI | C17: Ball Goni | E17: 1 | F17: 38.1 | G17: 1.1 | H17: =F17-G17 -> 37 | I17: -
A18: RAJANGAN | B18: KASTURI | C18: Ball Goni | E18: =E17+1 -> 2 | F18: 44.7 | G18: 1.1 | H18: =F18-G18 -> 43.6 | I18: -
A19: RAJANGAN | B19: KASTURI | C19: Ball Goni | E19: =E18+1 -> 3 | F19: 37.5 | G19: 1.1 | H19: =F19-G19 -> 36.4 | I19: -
A20: RAJANGAN | B20: KASTURI | C20: Ball Goni | E20: =E19+1 -> 4 | F20: 43.2 | G20: 1.6 | H20: =F20-G20 -> 41.6 | I20: -
A21: RAJANGAN | B21: KASTURI | C21: Ball Goni | E21: =E20+1 -> 5 | F21: 40.7 | G21: 1.2 | H21: =F21-G21 -> 39.5 | I21: -
A22: RAJANGAN | B22: KASTURI | C22: Ball Goni | E22: =E21+1 -> 6 | F22: 44.2 | G22: 1.4 | H22: =F22-G22 -> 42.8 | I22: -
A23: RAJANGAN | B23: KASTURI | C23: Ball Goni | E23: =E22+1 -> 7 | F23: 40.4 | G23: 1.6 | H23: =F23-G23 -> 38.8 | I23: -
A24: RAJANGAN | B24: KASTURI | C24: Ball Goni | E24: =E23+1 -> 8 | F24: 38.3 | G24: 1.9 | H24: =F24-G24 -> 36.4 | I24: -
A25: RAJANGAN | B25: KASTURI | C25: Ball Goni | E25: =E24+1 -> 9 | F25: 43.6 | G25: 1.1 | H25: =F25-G25 -> 42.5 | I25: -
A26: RAJANGAN | B26: KASTURI | C26: Ball Goni | E26: =E25+1 -> 10 | F26: 42.5 | G26: 2.1 | H26: =F26-G26 -> 40.4 | I26: -
A27: RAJANGAN | B27: KASTURI | C27: Ball Goni | E27: =E26+1 -> 11 | F27: 44.5 | G27: 0.8 | H27: =F27-G27 -> 43.7 | I27: -
A28: RAJANGAN | B28: KASTURI | C28: Ball Goni | E28: =E27+1 -> 12 | F28: 42.5 | G28: 1.1 | H28: =F28-G28 -> 41.4 | I28: -
A29: RAJANGAN | B29: KASTURI | C29: Ball Goni | E29: =E28+1 -> 13 | F29: 39.9 | G29: 1.3 | H29: =F29-G29 -> 38.6 | I29: -
... A112: RAJANGAN | B112: KASTURI | C112: Ball Goni | E112: =E111+1 -> 96 | F112: 46 | G112: 1.1 | H112: =F112-G112 -> 44.9 | I112: -
A113: GRAND TOTAL | E113: =E112 -> 96 | F113: =SUM(F17:F112) -> 4156.4 | G113: =SUM(G17:G112) -> 127.5 | H113: =SUM(H17:H112) -> 4028.9
A115: Separation Result :
A116: Product Type | B116: Origin | C116: Total Pack | D116: Pack Type | E116: Product Qty (Kg) | F116: Bits Stem Qty (Kg) | G116: Dust Qty (Kg) | H116: Uncountable Waste Qty (Kg) | I116: TOTAL Qty (Kg)
A117: RAJANGAN | B117: KASTURI | C117: =E113 -> 96 | D117: Ball Goni | E117: 3011.9 | F117: 916.5 | G117: 54.5 | H117: =H113-(E117+F117+G117) -> 46 | I117: =SUM(E117:H117) -> 4028.9
A118: PERCENTAGE (YIELD) | E118: =E117/$H$113 -> 0.74757378 | F118: =F117/$H$113 -> 0.22748145 | G118: =G117/$H$113 -> 0.013527266 | H118: =H117/$H$113 -> 0.011417509 | I118: =SUM(E118:H118) -> 1
A119: Remark :
A120: 1. Gross qty. based on actual weighing during the process.
A121: 2. Tare qty. based on actual weighing during the process.
A122: 3. Uncountable waste qty. based on teoritical calculation.
A123: 4. Percentage Yield based on total Nett. qty actual weighing.
A125: 2. Material Desc. | B125: : Rajangan Rembang
A126: Product Type | B126: Origin | C126: Pack Type | E126: No | F126: Gross (Kg) | G126: Tare (Kg) | H126: Netto ( Kg) | I126: Remark
A127: RAJANGAN | B127: REMBANG | C127: Ball Goni | E127: 1 | F127: 43.7 | G127: 1.7 | H127: =F127-G127 -> 42 | I127: -
A128: RAJANGAN | B128: REMBANG | C128: Ball Goni | E128: =E127+1 -> 2 | F128: 50.5 | G128: 1.7 | H128: =F128-G128 -> 48.8 | I128: -
...

Sheet SPR Batch 2
A1: PROCESS CERTIFICATE
A3: DELIVERY NOTE :
A4: Customer | B4: : Bpk. Bimo (PT. Falih Nur Gemilang) | G4: Issued Date : | H4: 46183
A6: Product Type | B6: Origin | C6: Pack Type | D6: Gross (Kg) | E6: Tare (Kg) | F6: Netto ( Kg) | G6: Date of Receipt | H6: Delivery Note Number
A7: RAJANGAN | B7: Maesan | C7: Ball Goni | D7: 410.9 | E7: 9.3 | F7: =D7-E7 -> 401.6 | G7: 46179 | H7: -
A8: RAJANGAN | B8: Paiton | C8: Ball Goni | D8: 753.2 | E8: 23.7 | F8: =D8-E8 -> 729.5 | G8: 46179 | H8: -
A9: RAJANGAN | B9: Ploso | C9: Ball Goni | D9: 281.5 | E9: 7.7 | F9: =D9-E9 -> 273.8 | G9: 46179 | H9: -
A10: RAJANGAN | B10: Lombok 24 | C10: Ball Goni | D10: 755.6 | E10: 27.7 | F10: =D10-E10 -> 727.9 | G10: 46179 | H10: -
A11: RAJANGAN | B11: Madura | C11: C48 | D11: 784.4 | E11: 122.4 | F11: =D11-E11 -> 662 | G11: 46179 | H11: -
A12: RAJANGAN | B12: Temanggung | C12: Sak | D12: 695.8 | E12: 5.6 | F12: =D12-E12 -> 690.2 | G12: 46179 | H12: -
A14: Remark :
A15: 1. Gross qty. Based on Surat Jalan.
A16: 2. Tare qty. Based on actual weighing during the process.
A18: SEPARATION RESULTS REPORT :
A19: 1. Material Desc. | B19: : Rajangan Maesan
A20: Product Type | B20: Origin | C20: Pack Type | D20: No | E20: Gross (Kg) | F20: Tare (Kg) | G20: Netto ( Kg) | H20: Remark
A21: RAJANGAN | B21: MAESAN | C21: Ball Goni | D21: 1 | E21: 44.4 | F21: 1.1 | G21: =E21-F21 -> 43.3 | H21: -
A22: RAJANGAN | B22: MAESAN | C22: Ball Goni | D22: =D21+1 -> 2 | E22: 45.7 | F22: 1.1 | G22: =E22-F22 -> 44.6 | H22: -
A23: RAJANGAN | B23: MAESAN | C23: Ball Goni | D23: =D22+1 -> 3 | E23: 50.5 | F23: 1.1 | G23: =E23-F23 -> 49.4 | H23: -
A24: RAJANGAN | B24: MAESAN | C24: Ball Goni | D24: =D23+1 -> 4 | E24: 62.7 | F24: 1.2 | G24: =E24-F24 -> 61.5 | H24: -
A25: RAJANGAN | B25: MAESAN | C25: Ball Goni | D25: =D24+1 -> 5 | E25: 48.1 | F25: 1.3 | G25: =E25-F25 -> 46.8 | H25: -
A26: RAJANGAN | B26: MAESAN | C26: Ball Goni | D26: =D25+1 -> 6 | E26: 51.3 | F26: 1.2 | G26: =E26-F26 -> 50.1 | H26: -
A27: RAJANGAN | B27: MAESAN | C27: Ball Goni | D27: =D26+1 -> 7 | E27: 56.4 | F27: 1.2 | G27: =E27-F27 -> 55.2 | H27: -
A28: RAJANGAN | B28: MAESAN | C28: Ball Goni | D28: =D27+1 -> 8 | E28: 55.6 | F28: 1.1 | G28: =E28-F28 -> 54.5 | H28: -
A29: GRAND TOTAL | D29: 8 | E29: =SUM(E21:E28) -> 414.7 | F29: =SUM(F21:F28) -> 9.3 | G29: =SUM(G21:G28) -> 405.4
A31: Separation Result :
A32: Product Type | B32: Origin | C32: Pack Type | D32: Product Qty (Kg) | E32: Bits Stem Qty (Kg) | F32: Dust Qty (Kg) | G32: Uncountable Waste Qty (Kg) | H32: TOTAL Qty (Kg)
A33: RAJANGAN | B33: MAESAN | C33: Ball Goni | D33: 285.1 | E33: 95.2 | F33: 6.8 | G33: =G29-(D33+E33+F33) -> 18.3 | H33: =SUM(D33:G33) -> 405.4
A34: PERCENTAGE (YIELD) | D34: =D33/$G$29 -> 0.70325604 | E34: =E33/$G$29 -> 0.2348298 | F34: =F33/$G$29 -> 0.016773557 | G34: =G33/$G$29 -> 0.045140602 | H34: =SUM(D34:G34) -> 1
A35: Remark :
A36: 1. Gross qty. based on actual weighing during the process.
A37: 2. Tare qty. based on actual weighing during the process.
A38: 3. Uncountable waste qty. based on teoritical calculation.
A39: 4. Percentage Yield based on total Nett. qty actual weighing.
A41: 2. Material Desc. | B41: : Rajangan Paiton
A42: Product Type | B42: Origin | C42: Pack Type | D42: No | E42: Gross (Kg) | F42: Tare (Kg) | G42: Netto ( Kg) | H42: Remark
A43: RAJANGAN | B43: PAITON | C43: Ball Goni | D43: 1 | E43: 49.6 | F43: 1.6 | G43: =E43-F43 -> 48 | H43: -
A44: RAJANGAN | B44: PAITON | C44: Ball Goni | D44: =D43+1 -> 2 | E44: 56 | F44: 1.7 | G44: =E44-F44 -> 54.3 | H44: -
A45: RAJANGAN | B45: PAITON | C45: Ball Goni | D45: =D44+1 -> 3 | E45: 59.3 | F45: 1.6 | G45: =E45-F45 -> 57.7 | H45: -
A46: RAJANGAN | B46: PAITON | C46: Ball Goni | D46: =D45+1 -> 4 | E46: 49.9 | F46: 1.9 | G46: =E46-F46 -> 48 | H46: -
...

Sheet SPR Batch 3 
A1: PROCESS CERTIFICATE
A3: DELIVERY NOTE :
A4: Customer | B4: : Bpk. Bimo (PT. Falih Nur Gemilang) | G4: Issued Date : | H4: 46186
A6: Product Type | B6: Origin | C6: Pack Type | D6: Gross (Kg) | E6: Tare (Kg) | F6: Netto ( Kg) | G6: Date of Receipt | H6: Delivery Note Number
A7: RAJANGAN | B7: Ploso | C7: Ball Goni | D7: 760.2 | E7: 23.9 | F7: =D7-E7 -> 736.3 | G7: 46181 | H7: -
A8: RAJANGAN | B8: Paiton | C8: Ball Goni | D8: 1116.9 | E8: 39.3 | F8: =D8-E8 -> 1077.6 | G8: 46181 | H8: -
A9: RAJANGAN | B9: Temanggung | C9: C-48 | D9: 796.4 | E9: 93 | F9: =D9-E9 -> 703.4 | G9: 46181 | H9: -
A10: RAJANGAN | B10: Lombok | C10: Ball Goni | D10: 1231.3 | E10: 48.7 | F10: =D10-E10 -> 1182.6 | G10: 46181 | H10: -
A11: RAJANGAN | B11: Madura | C11: C48 | D11: 784.4 | E11: 122.4 | F11: =D11-E11 -> 662 | G11: 46179 | H11: -
A12: RAJANGAN | B12: Temanggung | C12: Sak | D12: 695.8 | E12: 5.6 | F12: =D12-E12 -> 690.2 | G12: 46179 | H12: -
A14: Remark :
A15: 1. Gross qty. Based on Surat Jalan.
A16: 2. Tare qty. Based on actual weighing during the process.
A18: SEPARATION RESULTS REPORT :
A19: 1. Material Desc. | B19: : Rajangan Ploso
A20: Product Type | B20: Origin | C20: Pack Type | D20: No | E20: Gross (Kg) | F20: Tare (Kg) | G20: Netto ( Kg) | H20: Remark
A21: RAJANGAN | B21: PLOSO | C21: Ball Goni | D21: 1 | E21: 46.1 | F21: 1.3 | G21: =E21-F21 -> 44.8 | H21: -
A22: RAJANGAN | B22: PLOSO | C22: Ball Goni | D22: =D21+1 -> 2 | E22: 43.8 | F22: 1.2 | G22: =E22-F22 -> 42.6 | H22: -
A23: RAJANGAN | B23: PLOSO | C23: Ball Goni | D23: =D22+1 -> 3 | E23: 49.5 | F23: 1.3 | G23: =E23-F23 -> 48.2 | H23: -
A24: RAJANGAN | B24: PLOSO | C24: Ball Goni | D24: =D23+1 -> 4 | E24: 46 | F24: 1.2 | G24: =E24-F24 -> 44.8 | H24: -
A25: RAJANGAN | B25: PLOSO | C25: Ball Goni | D25: =D24+1 -> 5 | E25: 47.7 | F25: 1.5 | G25: =E25-F25 -> 46.2 | H25: -
A26: RAJANGAN | B26: PLOSO | C26: Ball Goni | D26: =D25+1 -> 6 | E26: 42.5 | F26: 1.5 | G26: =E26-F26 -> 41 | H26: -
A27: RAJANGAN | B27: PLOSO | C27: Ball Goni | D27: =D26+1 -> 7 | E27: 44.3 | F27: 1.6 | G27: =E27-F27 -> 42.7 | H27: -
A28: RAJANGAN | B28: PLOSO | C28: Ball Goni | D28: =D27+1 -> 8 | E28: 39.8 | F28: 1.4 | G28: =E28-F28 -> 38.4 | H28: -
A29: RAJANGAN | B29: PLOSO | C29: Ball Goni | D29: =D28+1 -> 9 | E29: 45.8 | F29: 1.5 | G29: =E29-F29 -> 44.3 | H29: -
A30: RAJANGAN | B30: PLOSO | C30: Ball Goni | D30: =D29+1 -> 10 | E30: 46 | F30: 1.9 | G30: =E30-F30 -> 44.1 | H30: -
A31: RAJANGAN | B31: PLOSO | C31: Ball Goni | D31: =D30+1 -> 11 | E31: 44.4 | F31: 1.7 | G31: =E31-F31 -> 42.7 | H31: -
A32: RAJANGAN | B32: PLOSO | C32: Ball Goni | D32: =D31+1 -> 12 | E32: 43.5 | F32: 1.5 | G32: =E32-F32 -> 42 | H32: -
A33: RAJANGAN | B33: PLOSO | C33: Ball Goni | D33: =D32+1 -> 13 | E33: 48.7 | F33: 1.3 | G33: =E33-F33 -> 47.4 | H33: -
... A37: RAJANGAN | B37: PLOSO | C37: Ball Goni | D37: =D36+1 -> 17 | E37: 45.3 | F37: 1.2 | G37: =E37-F37 -> 44.1 | H37: -
A38: GRAND TOTAL | D38: =D37 -> 17 | E38: =SUM(E21:E37) -> 765.4 | F38: =SUM(F21:F37) -> 23.9 | G38: =SUM(G21:G37) -> 741.5
A40: Separation Result :
A41: Product Type | B41: Origin | C41: Pack Type | D41: Product Qty (Kg) | E41: Bits Stem Qty (Kg) | F41: Dust Qty (Kg) | G41: Uncountable Waste Qty (Kg) | H41: TOTAL Qty (Kg)
A42: RAJANGAN | B42: PLOSO | C42: Ball Goni | D42: 563.3 | E42: 157.8 | F42: 6.5 | G42: =G38-(D42+E42+F42) -> 13.9 | H42: =SUM(D42:G42) -> 741.5
A43: PERCENTAGE (YIELD) | D43: =D42/$G$38 -> 0.75967633 | E43: =E42/$G$38 -> 0.21281187 | F43: =F42/$G$38 -> 0.0087660148 | G43: =G42/$G$38 -> 0.018745786 | H43: =SUM(D43:G43) -> 1
A44: Remark :
A45: 1. Gross qty. based on actual weighing during the process.
A46: 2. Tare qty. based on actual weighing during the process.
A47: 3. Uncountable waste qty. based on teoritical calculation.
A48: 4. Percentage Yield based on total Nett. qty actual weighing.
...

Sheet SPR Batch 4 
A1: PROCESS CERTIFICATE
A3: DELIVERY NOTE :
A4: Customer | B4: : Bpk. Bimo (PT. Falih Nur Gemilang) | G4: Issued Date : | H4: 46188
A6: Product Type | B6: Origin | C6: Pack Type | D6: Gross (Kg) | E6: Tare (Kg) | F6: Netto ( Kg) | G6: Date of Receipt | H6: Delivery Note Number | L6: Revisi | M6: selisih | N6: Keterangan
A7: RAJANGAN | B7: LOMBOK '24 | C7: Ball Goni | D7: 1221 | E7: 39.8 | F7: =D7-E7 -> 1181.2 | G7: 46183 | H7: - | J7: 25 | K7: =(28*30)+32.9 -> 872.9 | L7: 786.6 | M7: =K7-L7 -> 86.3 | N7: Simpan dan tunggu info setelah batch 1 selesai
A8: RAJANGAN | B8: PAITON | C8: Ball Goni | D8: 785.3 | E8: 22.4 | F8: =D8-E8 -> 762.9 | G8: 46183 | H8: - | J8: 17 | K8: =23*30 -> 690 | L8: 527.7 | M8: =K8-L8 -> 162.3 | N8: 1 sak ada di probolinggo, 132,3 kg itu kelebihannya terkirim
A9: RAJANGAN | B9: TEMANGGUNG | C9: Karung Sak | D9: 370.1 | E9: 3 | F9: =D9-E9 -> 367.1 | G9: 46183 | H9: - | J9: 15 | K9: =(5*40)+22.7 -> 222.7
A10: RAJANGAN | B10: MADURA'25 | C10: Ball Goni | D10: 505.5 | E10: 11.8 | F10: =D10-E10 -> 493.7 | G10: 46183 | H10: - | J10: 10
A11: RAJANGAN | B11: LOMBOK '25 | C11: Ball Goni | D11: 500.4 | E11: 11.4 | F11: =D11-E11 -> 489 | G11: 46183 | H11: - | J11: 10 | K11: =(1*25)+9.7 -> 34.7
A13: Remark :
A14: 1. Gross qty. Based on Delivery Note.
A15: 2. Tare qty. Based on actual weighing during the process.
A17: SEPARATION RESULTS REPORT :
A18: 1. Material Desc. | B18: : LOMBOK '24
A19: Product Type | B19: Origin | C19: Pack Type | D19: No | E19: Gross (Kg) | F19: Tare (Kg) | G19: Netto ( Kg) | H19: Remark
A20: RAJANGAN | B20: LOMBOK '24 | C20: Ball Goni | D20: 1 | E20: 46.6 | F20: 2 | G20: =E20-F20 -> 44.6 | H20: -
A21: RAJANGAN | B21: LOMBOK '24 | C21: Ball Goni | D21: =D20+1 -> 2 | E21: 46.8 | F21: 1.7 | G21: =E21-F21 -> 45.1 | H21: -
A22: RAJANGAN | B22: LOMBOK '24 | C22: Ball Goni | D22: =D21+1 -> 3 | E22: 48.4 | F22: 1.5 | G22: =E22-F22 -> 46.9 | H22: -
A23: RAJANGAN | B23: LOMBOK '24 | C23: Ball Goni | D23: =D22+1 -> 4 | E23: 47.9 | F23: 1.4 | G23: =E23-F23 -> 46.5 | H23: -
A24: RAJANGAN | B24: LOMBOK '24 | C24: Ball Goni | D24: =D23+1 -> 5 | E24: 44.4 | F24: 1.5 | G24: =E24-F24 -> 42.9 | H24: -
A25: RAJANGAN | B25: LOMBOK '24 | C25: Ball Goni | D25: =D24+1 -> 6 | E25: 48.8 | F25: 1.6 | G25: =E25-F25 -> 47.2 | H25: -
A26: RAJANGAN | B26: LOMBOK '24 | C26: Ball Goni | D26: =D25+1 -> 7 | E26: 47.3 | F26: 1.5 | G26: =E26-F26 -> 45.8 | H26: -
A27: RAJANGAN | B27: LOMBOK '24 | C27: Ball Goni | D27: =D26+1 -> 8 | E27: 49.6 | F27: 1.3 | G27: =E27-F27 -> 48.3 | H27: -
A28: RAJANGAN | B28: LOMBOK '24 | C28: Ball Goni | D28: =D27+1 -> 9 | E28: 44 | F28: 1.5 | G28: =E28-F28 -> 42.5 | H28: -
A29: RAJANGAN | B29: LOMBOK '24 | C29: Ball Goni | D29: =D28+1 -> 10 | E29: 43.9 | F29: 1.6 | G29: =E29-F29 -> 42.3 | H29: -
A30: RAJANGAN | B30: LOMBOK '24 | C30: Ball Goni | D30: =D29+1 -> 11 | E30: 43.2 | F30: 1.4 | G30: =E30-F30 -> 41.8 | H30: -
A31: RAJANGAN | B31: LOMBOK '24 | C31: Ball Goni | D31: =D30+1 -> 12 | E31: 49.2 | F31: 1.5 | G31: =E31-F31 -> 47.7 | H31: -
A32: RAJANGAN | B32: LOMBOK '24 | C32: Ball Goni | D32: =D31+1 -> 13 | E32: 44.9 | F32: 1.5 | G32: =E32-F32 -> 43.4 | H32: -
... A46: RAJANGAN | B46: LOMBOK '24 | C46: Ball Goni | D46: =D45+1 -> 27 | E46: 16.9 | F46: 0.2 | G46: =E46-F46 -> 16.7 | H46: Remnant
A47: GRAND TOTAL | D47: =D46 -> 27 | E47: =SUM(E20:E46) -> 1193 | F47: =SUM(F20:F46) -> 39.8 | G47: =SUM(G20:G46) -> 1153.2
A49: Separation Result :
A50: Product Type | B50: Origin | C50: Pack Type | D50: Product Qty (Kg) | E50: Bits Stem Qty (Kg) | F50: Dust Qty (Kg) | G50: Uncountable Waste Qty (Kg) | H50: TOTAL Qty (Kg)
A51: RAJANGAN | B51: =B46 -> LOMBOK '24 | C51: Ball Goni | D51: 786.6 | E51: 345.3 | F51: 12.5 | G51: =G47-(D51+E51+F51) -> 8.8 | H51: =SUM(D51:G51) -> 1153.2
A52: PERCENTAGE (YIELD) | D52: =D51/$G$47 -> 0.68210198 | E52: =E51/$G$47 -> 0.29942768 | F52: =F51/$G$47 -> 0.010839403 | G52: =G51/$G$47 -> 0.00763094 | H52: =SUM(D52:G52) -> 1
A53: Remark :
A54: 1. Gross qty. based on actual weighing during the process.
A55: 2. Tare qty. based on actual weighing during the process.
A56: 3. Uncountable waste qty. based on teoritical calculation.
A57: 4. Percentage Yield based on total Nett. qty actual weighing.
A59: 2. Material Desc. | B59: : PAITON
...

Sheet SPR Batch 5
A1: PROCESS CERTIFICATE
A3: DELIVERY NOTE :
A4: Customer | B4: : Bpk. Bimo (PT. Falih Nur Gemilang) | H4: Issued Date : | I4: 46199
A6: Product Type | B6: Origin | C6: Total Pack (Unit) | D6: Pack Type | E6: Gross (Kg) | F6: Tare (Kg) | G6: Netto ( Kg) | H6: Date of Receipt | I6: Delivery Note Number
A7: RAJANGAN | B7: LOMBOK P9 | C7: 20 | D7: Ball Goni | E7: 1013.4 | F7: 22.5 | G7: =E7-F7 -> 990.9 | H7: 46184 | I7: - | L7: 20
A8: RAJANGAN | B8: PAITON P10 | C8: 22 | D8: Ball Goni | E8: 1087.6 | F8: 27.7 | G8: =E8-F8 -> 1059.9 | H8: 46184 | I8: - | L8: 22 | M8: =E8*0.95% -> 10.3322
A9: RAJANGAN | B9: MADURA P11 | C9: 17 | D9: Ball Goni | E9: 843.3 | F9: 20.2 | G9: =E9-F9 -> 823.1 | H9: 46184 | I9: - | L9: 17 | M9: =E9*0.95% -> 8.01135
A10: RAJANGAN | B10: Madura | D10: C48 | E10: 784.4 | F10: 122.4 | G10: =E10-F10 -> 662 | H10: 46179 | I10: -
A11: RAJANGAN | B11: Temanggung | D11: Sak | E11: 695.8 | F11: 5.6 | G11: =E11-F11 -> 690.2 | H11: 46179 | I11: -
A12: Remark :
A13: 1. Gross qty. Based on Delivery Note.
A14: 2. Tare qty. Based on actual weighing during the process.
A16: SEPARATION RESULTS REPORT :
A17: 1. Material Desc : LOMBOK P9
A18: Product Type | B18: Origin | C18: Pack Type | E18: No | F18: Gross (Kg) | G18: Tare (Kg) | H18: Netto ( Kg) | I18: Remark
A19: RAJANGAN | B19: LOMBOK P9 | C19: Ball Goni | E19: 1 | F19: 52.4 | G19: 1 | H19: =F19-G19 -> 51.4 | I19: -
A20: RAJANGAN | B20: LOMBOK P9 | C20: Ball Goni | E20: =E19+1 -> 2 | F20: 50.9 | G20: 1 | H20: =F20-G20 -> 49.9 | I20: -
A21: RAJANGAN | B21: LOMBOK P9 | C21: Ball Goni | E21: =E20+1 -> 3 | F21: 48.3 | G21: 1.5 | H21: =F21-G21 -> 46.8 | I21: -
A22: RAJANGAN | B22: LOMBOK P9 | C22: Ball Goni | E22: =E21+1 -> 4 | F22: 52.2 | G22: 1 | H22: =F22-G22 -> 51.2 | I22: -
A23: RAJANGAN | B23: LOMBOK P9 | C23: Ball Goni | E23: =E22+1 -> 5 | F23: 51.6 | G23: 1.4 | H23: =F23-G23 -> 50.2 | I23: -
A24: RAJANGAN | B24: LOMBOK P9 | C24: Ball Goni | E24: =E23+1 -> 6 | F24: 52.3 | G24: 1.5 | H24: =F24-G24 -> 50.8 | I24: -
A25: RAJANGAN | B25: LOMBOK P9 | C25: Ball Goni | E25: =E24+1 -> 7 | F25: 51.1 | G25: 1 | H25: =F25-G25 -> 50.1 | I25: -
A26: RAJANGAN | B26: LOMBOK P9 | C26: Ball Goni | E26: =E25+1 -> 8 | F26: 48.9 | G26: 1 | H26: =F26-G26 -> 47.9 | I26: -
A27: RAJANGAN | B27: LOMBOK P9 | C27: Ball Goni | E27: =E26+1 -> 9 | F27: 48.7 | G27: 1.3 | H27: =F27-G27 -> 47.4 | I27: -
A28: RAJANGAN | B28: LOMBOK P9 | C28: Ball Goni | E28: =E27+1 -> 10 | F28: 53.9 | G28: 1.2 | H28: =F28-G28 -> 52.7 | I28: -
A29: RAJANGAN | B29: LOMBOK P9 | C29: Ball Goni | E29: =E28+1 -> 11 | F29: 51.8 | G29: 1.1 | H29: =F29-G29 -> 50.7 | I29: -
A30: RAJANGAN | B30: LOMBOK P9 | C30: Ball Goni | E30: =E29+1 -> 12 | F30: 50.5 | G30: 1.1 | H30: =F30-G30 -> 49.4 | I30: -
A31: RAJANGAN | B31: LOMBOK P9 | C31: Ball Goni | E31: =E30+1 -> 13 | F31: 51.5 | G31: 1.1 | H31: =F31-G31 -> 50.4 | I31: -
... A38: RAJANGAN | B38: LOMBOK P9 | C38: Ball Goni | E38: =E37+1 -> 20 | F38: 50.5 | G38: 0.8 | H38: =F38-G38 -> 49.7 | I38: -
A39: GRAND TOTAL | E39: =E38 -> 20 | F39: =SUM(F19:F38) -> 1015.2 | G39: =SUM(G19:G38) -> 22.5 | H39: =SUM(H19:H38) -> 992.7 | K39: =E7-F39 -> -1.8
A41: Separation Result :
A42: Product Type | B42: Origin | C42: Pack Type | E42: Product Qty (Kg) | F42: Bits Stem Qty (Kg) | G42: Dust Qty (Kg) | H42: Uncountable Waste Qty (Kg) | I42: TOTAL Qty (Kg)
A43: RAJANGAN | B43: LOMBOK P9 | C43: Ball Goni | E43: =614.8+50 -> 664.8 | F43: 306.2 | G43: 10.7 | H43: =IF(E43="","",(H39-E43-F43-G43)) -> 11 | I43: =IF(E43="","",SUM(E43:H43)) -> 992.7
A44: PERCENTAGE (YIELD) | E44: =IF(E43="","",E43/$H$39) -> 0.66968873 | F44: =IF(F43="","",F43/$H$39) -> 0.3084517 | G44: =IF(G43="","",G43/$H$39) -> 0.010778684 | H44: =IF(H43="","",H43/$H$39) -> 0.011080891 | I44: =IF(I43="","",SUM(E44:H44)) -> 1
A45: Remark :
A46: 1. Gross qty. based on actual weighing during the process.
A47: 2. Tare qty. based on actual weighing during the process.
A48: 3. Uncountable waste qty. based on teoritical calculation.
A49: 4. Percentage Yield based on total Nett. qty actual weighing.
A51: 2. Material Desc : PAITON P10
...

Sheet SPR Batch6
A1: PROCESS CERTIFICATE
A3: DELIVERY NOTE :
A4: Customer | B4: : Bpk. Bimo (PT. Falih Nur Gemilang) | H4: Issued Date : | I4: 46199
A6: Product Type | B6: Origin | C6: Total Pack (Unit) | D6: Pack Type | E6: Gross (Kg) | F6: Tare (Kg) | G6: Netto ( Kg) | H6: Date of Receipt | I6: Delivery Note Number
A7: RAJANGAN | B7: LOMBOK '25 | C7: 29 | D7: Ball Goni | E7: 1350.5 | F7: 49.4 | G7: =E7-F7 -> 1301.1 | H7: 46185 | I7: - | L7: 29
A8: RAJANGAN | B8: PAITON P10-5 | C8: 28 | D8: Ball Goni | E8: 1363 | F8: 32.4 | G8: =E8-F8 -> 1330.6 | H8: 46185 | I8: - | L8: 28
A9: RAJANGAN | B9: TEMANGGUNG | C9: 4 | D9: C48 | E9: 367.2 | F9: 61.9 | G9: =E9-F9 -> 305.3 | H9: 46185 | I9: - | L9: 4
A10: RAJANGAN | B10: Madura | D10: C48 | E10: 784.4 | F10: 122.4 | G10: =E10-F10 -> 662 | H10: 46179 | I10: -
A11: RAJANGAN | B11: Temanggung | D11: Sak | E11: 695.8 | F11: 5.6 | G11: =E11-F11 -> 690.2 | H11: 46179 | I11: -
A13: Remark :
A14: 1. Gross qty. Based on Delivery Note.
A15: 2. Tare qty. Based on actual weighing during the process.
A17: SEPARATION RESULTS REPORT :
A18: 1. Material Desc : LOMBOK '25
A19: Product Type | B19: Origin | C19: Pack Type | E19: No | F19: Gross (Kg) | G19: Tare (Kg) | H19: Netto ( Kg) | I19: Remark
A20: RAJANGAN | B20: LOMBOK '25 | C20: Ball Goni | E20: 1 | F20: 48.8 | G20: 1.5 | H20: =F20-G20 -> 47.3 | I20: -
A21: RAJANGAN | B21: LOMBOK '25 | C21: Ball Goni | E21: =E20+1 -> 2 | F21: 48.1 | G21: 1.8 | H21: =F21-G21 -> 46.3 | I21: -
A22: RAJANGAN | B22: LOMBOK '25 | C22: Ball Goni | E22: =E21+1 -> 3 | F22: 45.1 | G22: 1.4 | H22: =F22-G22 -> 43.7 | I22: -
A23: RAJANGAN | B23: LOMBOK '25 | C23: Ball Goni | E23: =E22+1 -> 4 | F23: 49.4 | G23: 1.6 | H23: =F23-G23 -> 47.8 | I23: -
A24: RAJANGAN | B24: LOMBOK '25 | C24: Ball Goni | E24: =E23+1 -> 5 | F24: 48.4 | G24: 1.5 | H24: =F24-G24 -> 46.9 | I24: -
A25: RAJANGAN | B25: LOMBOK '25 | C25: Ball Goni | E25: =E24+1 -> 6 | F25: 46.4 | G25: 1.9 | H25: =F25-G25 -> 44.5 | I25: -
A26: RAJANGAN | B26: LOMBOK '25 | C26: Ball Goni | E26: =E25+1 -> 7 | F26: 50.2 | G26: 1.4 | H26: =F26-G26 -> 48.8 | I26: -
A27: RAJANGAN | B27: LOMBOK '25 | C27: Ball Goni | E27: =E26+1 -> 8 | F27: 39.6 | G27: 1.9 | H27: =F27-G27 -> 37.7 | I27: -
A28: RAJANGAN | B28: LOMBOK '25 | C28: Ball Goni | E28: =E27+1 -> 9 | F28: 47.1 | G28: 1.7 | H28: =F28-G28 -> 45.4 | I28: -
A29: RAJANGAN | B29: LOMBOK '25 | C29: Ball Goni | E29: =E28+1 -> 10 | F29: 52.2 | G29: 1.5 | H29: =F29-G29 -> 50.7 | I29: -
A30: RAJANGAN | B30: LOMBOK '25 | C30: Ball Goni | E30: =E29+1 -> 11 | F30: 49 | G30: 1.7 | H30: =F30-G30 -> 47.3 | I30: -
A31: RAJANGAN | B31: LOMBOK '25 | C31: Ball Goni | E31: =E30+1 -> 12 | F31: 45.2 | G31: 1.8 | H31: =F31-G31 -> 43.4 | I31: -
A32: RAJANGAN | B32: LOMBOK '25 | C32: Ball Goni | E32: =E31+1 -> 13 | F32: 44.9 | G32: 1.9 | H32: =F32-G32 -> 43 | I32: -
... A48: RAJANGAN | B48: LOMBOK '25 | C48: Ball Goni | E48: =E47+1 -> 29 | F48: 37.4 | G48: 1.4 | H48: =F48-G48 -> 36 | I48: -
A49: GRAND TOTAL | E49: =E48 -> 29 | F49: =SUM(F20:F48) -> 1351.2 | G49: =SUM(G20:G48) -> 49.4 | H49: =SUM(H20:H48) -> 1301.8 | K49: =E7-F49 -> -0.7
A51: Separation Result :
A52: Product Type | B52: Origin | C52: Pack Type | E52: Product Qty (Kg) | F52: Bits Stem Qty (Kg) | G52: Dust Qty (Kg) | H52: Uncountable Waste Qty (Kg) | I52: TOTAL Qty (Kg)
A53: RAJANGAN | B53: LOMBOK '25 | C53: Ball Goni | E53: 827.2 | F53: 443.4 | G53: 17.9 | H53: =IF(E53="","",(H49-E53-F53-G53)) -> 13.3 | I53: =IF(E53="","",SUM(E53:H53)) -> 1301.8
A54: PERCENTAGE (YIELD) | E54: =IF(E53="","",E53/$H49) -> 0.63542787 | F54: =IF(F53="","",F53/$H49) -> 0.34060532 | G54: =IF(G53="","",G53/$H49) -> 0.013750192 | H54: =IF(H53="","",H53/$H49) -> 0.010216623 | I54: =IF(I53="","",SUM(E54:H54)) -> 1
A55: Remark :
A56: 1. Gross qty. based on actual weighing during the process.
A57: 2. Tare qty. based on actual weighing during the process.
A58: 3. Uncountable waste qty. based on teoritical calculation.
A59: 4. Percentage Yield based on total Nett. qty actual weighing.
A61: 2. Material Desc : PAITON P10-5
...

Sheet SPR Batch 7
A1: PROCESS CERTIFICATE
A3: DELIVERY NOTE :
A4: Customer | B4: : Bpk. Bimo (PT. Falih Nur Gemilang) | H4: Issued Date : | I4: 46199
A6: Product Type | B6: Origin | C6: Total Pack (Unit) | D6: Pack Type | E6: Gross (Kg) | F6: Tare (Kg) | G6: Netto ( Kg) | H6: Date of Receipt | I6: Delivery Note Number
A7: RAJANGAN | B7: LOMBOK | C7: 41 | D7: Ball Goni | E7: 1892.1 | F7: 65.1 | G7: =E7-F7 -> 1827 | H7: 46188 | I7: -
A8: RAJANGAN | B8: KASTURI | C8: 10 | D8: Ball Goni | E8: 424.6 | F8: 11.1 | G8: =E8-F8 -> 413.5 | H8: 46188 | I8: -
A9: RAJANGAN | B9: TEMANGGUNG | C9: 40 | D9: Sak | E9: 816 | F9: 16 | G9: =E9-F9 -> 800 | H9: 46188 | I9: -
A10: RAJANGAN | B10: Madura | D10: C48 | E10: 784.4 | F10: 122.4 | G10: =E10-F10 -> 662 | H10: 46179 | I10: -
A11: RAJANGAN | B11: Temanggung | D11: Sak | E11: 695.8 | F11: 5.6 | G11: =E11-F11 -> 690.2 | H11: 46179 | I11: -
A13: Remark :
A14: 1. Gross qty. Based on Delivery Note.
A15: 2. Tare qty. Based on actual weighing during the process.
A17: SEPARATION RESULTS REPORT :
A18: 1. Material Desc : LOMBOK
A19: Product Type | B19: Origin | C19: Pack Type | E19: No | F19: Gross (Kg) | G19: Tare (Kg) | H19: Netto ( Kg) | I19: Remark
A20: RAJANGAN | B20: LOMBOK | C20: Ball Goni | E20: 1 | F20: 52 | G20: 1.5 | H20: =F20-G20 -> 50.5 | I20: -
A21: RAJANGAN | B21: LOMBOK | C21: Ball Goni | E21: =E20+1 -> 2 | F21: 48.2 | G21: 1.7 | H21: =F21-G21 -> 46.5 | I21: -
A22: RAJANGAN | B22: LOMBOK | C22: Ball Goni | E22: =E21+1 -> 3 | F22: 50.7 | G22: 1.8 | H22: =F22-G22 -> 48.9 | I22: -
A23: RAJANGAN | B23: LOMBOK | C23: Ball Goni | E23: =E22+1 -> 4 | F23: 48.9 | G23: 1.4 | H23: =F23-G23 -> 47.5 | I23: -
A24: RAJANGAN | B24: LOMBOK | C24: Ball Goni | E24: =E23+1 -> 5 | F24: 43.9 | G24: 1.5 | H24: =F24-G24 -> 42.4 | I24: -
A25: RAJANGAN | B25: LOMBOK | C25: Ball Goni | E25: =E24+1 -> 6 | F25: 51.8 | G25: 1.3 | H25: =F25-G25 -> 50.5 | I25: -
A26: RAJANGAN | B26: LOMBOK | C26: Ball Goni | E26: =E25+1 -> 7 | F26: 43.4 | G26: 1.7 | H26: =F26-G26 -> 41.7 | I26: -
A27: RAJANGAN | B27: LOMBOK | C27: Ball Goni | E27: =E26+1 -> 8 | F27: 41.7 | G27: 1.8 | H27: =F27-G27 -> 39.9 | I27: -
A28: RAJANGAN | B28: LOMBOK | C28: Ball Goni | E28: =E27+1 -> 9 | F28: 42.6 | G28: 1.5 | H28: =F28-G28 -> 41.1 | I28: -
A29: RAJANGAN | B29: LOMBOK | C29: Ball Goni | E29: =E28+1 -> 10 | F29: 40.7 | G29: 1.7 | H29: =F29-G29 -> 39 | I29: -
A30: RAJANGAN | B30: LOMBOK | C30: Ball Goni | E30: =E29+1 -> 11 | F30: 42.9 | G30: 1.9 | H30: =F30-G30 -> 41 | I30: -
A31: RAJANGAN | B31: LOMBOK | C31: Ball Goni | E31: =E30+1 -> 12 | F31: 44.9 | G31: 1.5 | H31: =F31-G31 -> 43.4 | I31: -
A32: RAJANGAN | B32: LOMBOK | C32: Ball Goni | E32: =E31+1 -> 13 | F32: 47.8 | G32: 1.4 | H32: =F32-G32 -> 46.4 | I32: -
... A60: RAJANGAN | B60: LOMBOK | C60: Ball Goni | E60: =E59+1 -> 41 | F60: 46.9 | G60: 1.1 | H60: =F60-G60 -> 45.8 | I60: -
A61: GRAND TOTAL | E61: =E60 -> 41 | F61: =SUM(F20:F60) -> 1891.5 | G61: =SUM(G20:G60) -> 65.1 | H61: =SUM(H20:H60) -> 1826.4 | K61: =E7-F61 -> 0.6
A63: Separation Result :
A64: Product Type | B64: Origin | C64: Pack Type | E64: Product Qty (Kg) | F64: Bits Stem Qty (Kg) | G64: Dust Qty (Kg) | H64: Uncountable Waste Qty (Kg) | I64: TOTAL Qty (Kg)
A65: RAJANGAN | B65: LOMBOK | C65: Ball Goni | E65: 1195.4 | F65: 600.6 | G65: 26.7 | H65: =IF(E65="","",(H61-E65-F65-G65)) -> 3.7 | I65: =IF(E65="","",SUM(E65:H65)) -> 1826.4
A66: PERCENTAGE (YIELD) | E66: =IF(E65="","",E65/$H61) -> 0.65451161 | F66: =IF(F65="","",F65/$H61) -> 0.32884363 | G66: =IF(G65="","",G65/$H61) -> 0.014618922 | H66: =IF(H65="","",H65/$H61) -> 0.0020258432 | I66: =IF(I65="","",SUM(E66:H66)) -> 1
A67: Remark :
A68: 1. Gross qty. based on actual weighing during the process.
A69: 2. Tare qty. based on actual weighing during the process.
A70: 3. Uncountable waste qty. based on teoritical calculation.
A71: 4. Percentage Yield based on total Nett. qty actual weighing.
A73: 2. Material Desc : KASTURI
...

Sheet SPR Batch8
A1: PROCESS CERTIFICATE
A3: DELIVERY NOTE :
A4: Customer | B4: : Bpk. Bimo (PT. Falih Nur Gemilang) | H4: Issued Date : | I4: 46205
A6: Product Type | B6: Origin | C6: Total Pack (Unit) | D6: Pack Type | E6: Gross (Kg) | F6: Tare (Kg) | G6: Netto ( Kg) | H6: Date of Receipt | I6: Delivery Note Number
A7: RAJANGAN | B7: LOMBOK'24 | C7: 23 | D7: Ball Goni | E7: 1055.6 | F7: =G43 -> 35.2 | G7: =E7-F7 -> 1020.4 | H7: 46190 | I7: -
A8: RAJANGAN | B8: PAITON P10 | C8: 11 | D8: Ball Goni | E8: 541.6 | F8: =G68 -> 13.5 | G8: =E8-F8 -> 528.1 | H8: 46190 | I8: -
A9: RAJANGAN | B9: MADURA '25 | C9: 11 | D9: Ball Goni | E9: 545.7 | F9: =G92 -> 18.9 | G9: =E9-F9 -> 526.8 | H9: 46190 | I9: -
A10: RAJANGAN | B10: TEMANGGUNG | C10: 4 | D10: C48 | E10: 463.6 | F10: =G109 -> 55.5 | G10: =E10-F10 -> 408.1 | H10: 46190 | I10: -
A11: RAJANGAN | B11: KASTURI | C11: 13 | D11: Ball Goni | E11: 540.7 | F11: =G135 -> 17.9 | G11: =E11-F11 -> 522.8 | H11: 46190 | I11: -
A13: Remark :
A14: 1. Gross qty. Based on Delivery Note.
A15: 2. Tare qty. Based on actual weighing during the process.
A17: SEPARATION RESULTS REPORT :
A18: 1. Material Desc. | B18: : LOMBOK '24
A19: Product Type | B19: Origin | C19: Pack Type | E19: No | F19: Gross (Kg) | G19: Tare (Kg) | H19: Netto ( Kg) | I19: Remark
A20: RAJANGAN | B20: LOMBOK '24 | C20: Ball Goni | E20: 1 | F20: 49.1 | G20: 1.4 | H20: =F20-G20 -> 47.7 | I20: -
A21: RAJANGAN | B21: LOMBOK '24 | C21: Ball Goni | E21: =E20+1 -> 2 | F21: 42.7 | G21: 1.3 | H21: =F21-G21 -> 41.4 | I21: -
A22: RAJANGAN | B22: LOMBOK '24 | C22: Ball Goni | E22: =E21+1 -> 3 | F22: 40.6 | G22: 1.8 | H22: =F22-G22 -> 38.8 | I22: -
A23: RAJANGAN | B23: LOMBOK '24 | C23: Ball Goni | E23: =E22+1 -> 4 | F23: 47.5 | G23: 1.4 | H23: =F23-G23 -> 46.1 | I23: -
A24: RAJANGAN | B24: LOMBOK '24 | C24: Ball Goni | E24: =E23+1 -> 5 | F24: 47.7 | G24: 2.1 | H24: =F24-G24 -> 45.6 | I24: -
A25: RAJANGAN | B25: LOMBOK '24 | C25: Ball Goni | E25: =E24+1 -> 6 | F25: 47.4 | G25: 1.4 | H25: =F25-G25 -> 46 | I25: -
A26: RAJANGAN | B26: LOMBOK '24 | C26: Ball Goni | E26: =E25+1 -> 7 | F26: 53.9 | G26: 1.3 | H26: =F26-G26 -> 52.6 | I26: -
A27: RAJANGAN | B27: LOMBOK '24 | C27: Ball Goni | E27: =E26+1 -> 8 | F27: 48.8 | G27: 1.7 | H27: =F27-G27 -> 47.1 | I27: -
A28: RAJANGAN | B28: LOMBOK '24 | C28: Ball Goni | E28: =E27+1 -> 9 | F28: 45.1 | G28: 1.3 | H28: =F28-G28 -> 43.8 | I28: -
A29: RAJANGAN | B29: LOMBOK '24 | C29: Ball Goni | E29: =E28+1 -> 10 | F29: 37.2 | G29: 1.4 | H29: =F29-G29 -> 35.8 | I29: -
A30: RAJANGAN | B30: LOMBOK '24 | C30: Ball Goni | E30: =E29+1 -> 11 | F30: 42.1 | G30: 1.4 | H30: =F30-G30 -> 40.7 | I30: -
A31: RAJANGAN | B31: LOMBOK '24 | C31: Ball Goni | E31: =E30+1 -> 12 | F31: 49.1 | G31: 1.5 | H31: =F31-G31 -> 47.6 | I31: -
A32: RAJANGAN | B32: LOMBOK '24 | C32: Ball Goni | E32: =E31+1 -> 13 | F32: 45.5 | G32: 1.5 | H32: =F32-G32 -> 44 | I32: -
... A42: RAJANGAN | B42: LOMBOK '24 | C42: Ball Goni | E42: =E41+1 -> 23 | F42: 52.5 | G42: 1.8 | H42: =F42-G42 -> 50.7 | I42: -
A43: GRAND TOTAL | E43: =E42 -> 23 | F43: =SUM(F20:F42) -> 1085.8 | G43: =SUM(G20:G42) -> 35.2 | H43: =SUM(H20:H42) -> 1050.6
A45: Separation Result :
A46: Product Type | B46: Origin | C46: Pack Type | E46: Product Qty (Kg) | F46: Bits Stem Qty (Kg) | G46: Dust Qty (Kg) | H46: Uncountable Waste Qty (Kg) | I46: TOTAL Qty (Kg)
A47: RAJANGAN | B47: =B42 -> LOMBOK '24 | C47: Ball Goni | E47: 758.3 | F47: 263.6 | G47: 15.4 | H47: =IF(E47="","",(H43-E47-F47-G47)) -> 13.3 | I47: =IF(E47="","",SUM(E47:H47)) -> 1050.6
A48: PERCENTAGE (YIELD) | E48: =IF(E47="","",E47/$H43) -> 0.72177803 | F48: =IF(F47="","",F47/$H43) -> 0.25090425 | G48: =IF(G47="","",G47/$H43) -> 0.014658291 | H48: =IF(H47="","",H47/$H43) -> 0.012659433 | I48: =IF(I47="","",SUM(E48:H48)) -> 1
A49: Remark :
A50: 1. Gross qty. based on actual weighing during the process.
A51: 2. Tare qty. based on actual weighing during the process.
A52: 3. Uncountable waste qty. based on teoritical calculation.
A53: 4. Percentage Yield based on total Nett. qty actual weighing.
A55: 2. Material Desc. | B55: : PAITON P10
...

Sheet SPR Batch9
A1: PROCESS CERTIFICATE
A3: DELIVERY NOTE :
A4: Customer | B4: : Bpk. Bimo (PT. Falih Nur Gemilang) | H4: Issued Date : | I4: 46204
A6: Product Type | B6: Origin | C6: Total Pack (Unit) | D6: Pack Type | E6: Gross (Kg) | F6: Tare (Kg) | G6: Netto ( Kg) | H6: Date of Receipt | I6: Delivery Note Number
A7: RAJANGAN | B7: LOMBOK'24 | C7: 30 | D7: Ball Goni | E7: 1408.6 | F7: 44.2 | G7: =E7-F7 -> 1364.4 | H7: 46191 | I7: -
A8: RAJANGAN | B8: TEMANGGUNG | C8: 8 | D8: C48 | E8: 1066.5 | F8: =G71 -> 122.2 | G8: =E8-F8 -> 944.3 | H8: 46191 | I8: -
A9: RAJANGAN | B9: MADURA '25 | C9: 15 | D9: Ball Goni | E9: 732.1 | F9: 18.4 | G9: =E9-F9 -> 713.7 | H9: 46191 | I9: -
A10: RAJANGAN | B10: MADURA '25 | C10: 5 | D10: Karung Sak | E10: 68.6 | F10: 1.5 | G10: =E10-F10 -> 67.1 | H10: 46191 | I10: -
A12: Remark :
A13: 1. Gross qty. Based on Delivery Note.
A14: 2. Tare qty. Based on actual weighing during the process.
A16: SEPARATION RESULTS REPORT :
A17: 1. Material Desc. | B17: : LOMBOK '24
A18: Product Type | B18: Origin | C18: Pack Type | E18: No | F18: Gross (Kg) | G18: Tare (Kg) | H18: Netto ( Kg) | I18: Remark
A19: RAJANGAN | B19: LOMBOK '24 | C19: Ball Goni | E19: 1 | F19: 41.5 | G19: 1.5 | H19: =F19-G19 -> 40 | I19: -
A20: RAJANGAN | B20: LOMBOK '24 | C20: Ball Goni | E20: =E19+1 -> 2 | F20: 45.7 | G20: 1.3 | H20: =F20-G20 -> 44.4 | I20: -
A21: RAJANGAN | B21: LOMBOK '24 | C21: Ball Goni | E21: =E20+1 -> 3 | F21: 52.8 | G21: 1.3 | H21: =F21-G21 -> 51.5 | I21: -
A22: RAJANGAN | B22: LOMBOK '24 | C22: Ball Goni | E22: =E21+1 -> 4 | F22: 47.6 | G22: 1.7 | H22: =F22-G22 -> 45.9 | I22: -
A23: RAJANGAN | B23: LOMBOK '24 | C23: Ball Goni | E23: =E22+1 -> 5 | F23: 44.9 | G23: 1.7 | H23: =F23-G23 -> 43.2 | I23: -
A24: RAJANGAN | B24: LOMBOK '24 | C24: Ball Goni | E24: =E23+1 -> 6 | F24: 49.2 | G24: 1.5 | H24: =F24-G24 -> 47.7 | I24: -
A25: RAJANGAN | B25: LOMBOK '24 | C25: Ball Goni | E25: =E24+1 -> 7 | F25: 49.7 | G25: 1.5 | H25: =F25-G25 -> 48.2 | I25: -
A26: RAJANGAN | B26: LOMBOK '24 | C26: Ball Goni | E26: =E25+1 -> 8 | F26: 49.8 | G26: 1.3 | H26: =F26-G26 -> 48.5 | I26: -
A27: RAJANGAN | B27: LOMBOK '24 | C27: Ball Goni | E27: =E26+1 -> 9 | F27: 46.8 | G27: 1.6 | H27: =F27-G27 -> 45.2 | I27: -
A28: RAJANGAN | B28: LOMBOK '24 | C28: Ball Goni | E28: =E27+1 -> 10 | F28: 46.7 | G28: 1.4 | H28: =F28-G28 -> 45.3 | I28: -
A29: RAJANGAN | B29: LOMBOK '24 | C29: Ball Goni | E29: =E28+1 -> 11 | F29: 48.6 | G29: 1.5 | H29: =F29-G29 -> 47.1 | I29: -
A30: RAJANGAN | B30: LOMBOK '24 | C30: Ball Goni | E30: =E29+1 -> 12 | F30: 49 | G30: 1.4 | H30: =F30-G30 -> 47.6 | I30: -
A31: RAJANGAN | B31: LOMBOK '24 | C31: Ball Goni | E31: =E30+1 -> 13 | F31: 46.1 | G31: 1.5 | H31: =F31-G31 -> 44.6 | I31: -
... A48: RAJANGAN | B48: LOMBOK '24 | C48: Ball Goni | E48: =E47+1 -> 30 | F48: 48.7 | G48: 1.7 | H48: =F48-G48 -> 47 | I48: -
A49: GRAND TOTAL | E49: =E48 -> 30 | F49: =SUM(F19:F48) -> 1413.4 | G49: =SUM(G19:G48) -> 44.2 | H49: =SUM(H19:H48) -> 1369.2 | K49: =E7-F49 -> -4.8
A51: Separation Result :
A52: Product Type | B52: Origin | C52: Pack Type | E52: Product Qty (Kg) | F52: Bits Stem Qty (Kg) | G52: Dust Qty (Kg) | H52: Uncountable Waste Qty (Kg) | I52: TOTAL Qty (Kg)
A53: RAJANGAN | B53: =B48 -> LOMBOK '24 | C53: Ball Goni | E53: 1007 | F53: 467.9 | G53: 16.4 | H53: =IF(E53="","",(H49-E53-F53-G53)) -> -122.1 | I53: =IF(E53="","",SUM(E53:H53)) -> 1369.2 | K53: =1007-E53 -> 0 | L53: =342.9+125 -> 467.9
A54: PERCENTAGE (YIELD) | E54: =IF(E53="","",E53/$H49) -> 0.73546597 | F54: =IF(F53="","",F53/$H49) -> 0.3417324 | G54: =IF(G53="","",G53/$H49) -> 0.011977797 | H54: =IF(H53="","",H53/$H49) -> -0.089176161 | I54: =IF(I53="","",SUM(E54:H54)) -> 1
A55: Remark :
A56: 1. Gross qty. based on actual weighing during the process.
A57: 2. Tare qty. based on actual weighing during the process.
A58: 3. Uncountable waste qty. based on teoritical calculation.
A59: 4. Percentage Yield based on total Nett. qty actual weighing.
A61: 2. Material Desc. | B61: : TEMANGGUNG
A62: Product Type | B62: Origin | C62: Pack Type | E62: No | F62: Gross (Kg) | G62: Tare (Kg) | H62: Netto ( Kg) | I62: Remark
...

Sheet SPR Batch10
A1: PROCESS CERTIFICATE
A3: DELIVERY NOTE :
A4: Customer | B4: : Bpk. Bimo (PT. Falih Nur Gemilang) | H4: Issued Date : | I4: 46221
A6: Product Type | B6: Origin | C6: Total Pack (Unit) | D6: Pack Type | E6: Gross (Kg) | F6: Tare (Kg) | G6: Netto ( Kg) | H6: Date of Receipt | I6: Delivery Note Number
A7: RAJANGAN | B7: PAITON P10 | C7: 30 | D7: Ball Goni | E7: 1495 | F7: =G47 -> 34.6 | G7: =E7-F7 -> 1460.4 | H7: 46192 | I7: -
A8: RAJANGAN | B8: TEMANGGUNG | C8: 6 | D8: C48 | E8: 826.8 | F8: =G67 -> 90.9 | G8: =E8-F8 -> 735.9 | H8: 46192 | I8: - | K8: =E8/C8 -> 137.8
A10: Remark :
A11: 1. Gross qty. Based on Delivery Note.
A12: 2. Tare qty. Based on actual weighing during the process.
A14: SEPARATION RESULTS REPORT :
A15: 1. Material Desc. | B15: : PAITON P10
A16: Product Type | B16: Origin | C16: Pack Type | E16: No | F16: Gross (Kg) | G16: Tare (Kg) | H16: Netto ( Kg) | I16: Remark
A17: RAJANGAN | B17: PAITON | C17: Ball Goni | E17: 1 | F17: 47 | G17: 1.3 | H17: =F17-G17 -> 45.7 | I17: -
A18: RAJANGAN | B18: PAITON | C18: Ball Goni | E18: =E17+1 -> 2 | F18: 54 | G18: 1.1 | H18: =F18-G18 -> 52.9 | I18: -
A19: RAJANGAN | B19: PAITON | C19: Ball Goni | E19: =E18+1 -> 3 | F19: 51 | G19: 1.3 | H19: =F19-G19 -> 49.7 | I19: -
A20: RAJANGAN | B20: PAITON | C20: Ball Goni | E20: =E19+1 -> 4 | F20: 53.8 | G20: 1.6 | H20: =F20-G20 -> 52.2 | I20: -
A21: RAJANGAN | B21: PAITON | C21: Ball Goni | E21: =E20+1 -> 5 | F21: 56.1 | G21: 1.1 | H21: =F21-G21 -> 55 | I21: -
A22: RAJANGAN | B22: PAITON | C22: Ball Goni | E22: =E21+1 -> 6 | F22: 49 | G22: 1 | H22: =F22-G22 -> 48 | I22: -
A23: RAJANGAN | B23: PAITON | C23: Ball Goni | E23: =E22+1 -> 7 | F23: 50.9 | G23: 1.1 | H23: =F23-G23 -> 49.8 | I23: -
A24: RAJANGAN | B24: PAITON | C24: Ball Goni | E24: =E23+1 -> 8 | F24: 55.8 | G24: 1.2 | H24: =F24-G24 -> 54.6 | I24: -
A25: RAJANGAN | B25: PAITON | C25: Ball Goni | E25: =E24+1 -> 9 | F25: 49 | G25: 1.1 | H25: =F25-G25 -> 47.9 | I25: -
A26: RAJANGAN | B26: PAITON | C26: Ball Goni | E26: =E25+1 -> 10 | F26: 47.6 | G26: 1.3 | H26: =F26-G26 -> 46.3 | I26: -
A27: RAJANGAN | B27: PAITON | C27: Ball Goni | E27: =E26+1 -> 11 | F27: 51.7 | G27: 1 | H27: =F27-G27 -> 50.7 | I27: -
A28: RAJANGAN | B28: PAITON | C28: Ball Goni | E28: =E27+1 -> 12 | F28: 52.2 | G28: 1.1 | H28: =F28-G28 -> 51.1 | I28: -
A29: RAJANGAN | B29: PAITON | C29: Ball Goni | E29: =E28+1 -> 13 | F29: 44.2 | G29: 1.1 | H29: =F29-G29 -> 43.1 | I29: -
... A40: RAJANGAN | B40: PAITON | C40: Ball Goni | E40: =E39+1 -> 24 | F40: 52.5 | G40: 1 | H40: =F40-G40 -> 51.5 | I40: -
A41: RAJANGAN | B41: PAITON | C41: Ball Goni | E41: =E40+1 -> 25 | F41: 47.5 | G41: 1.2 | H41: =F41-G41 -> 46.3 | I41: - | L41: 50.1 | M41: 1.3
A42: RAJANGAN | B42: PAITON | C42: Ball Goni | E42: =E41+1 -> 26 | F42: 45.7 | G42: 0.9 | H42: =F42-G42 -> 44.8 | I42: - | L42: 20.2 | M42: 0.2
A43: RAJANGAN | B43: PAITON | C43: Ball Goni | E43: =E42+1 -> 27 | F43: 49.3 | G43: 1.1 | H43: =F43-G43 -> 48.2 | I43: - | L43: 22.9 | M43: 0.2
A44: RAJANGAN | B44: PAITON | C44: Ball Goni | E44: =E43+1 -> 28 | F44: 50.4 | G44: 1.2 | H44: =F44-G44 -> 49.2 | I44: - | L44: =SUM(L41:L43) -> 93.2 | M44: =SUM(M41:M43) -> 1.7
A45: RAJANGAN | B45: PAITON | C45: Ball Goni | E45: =E44+1 -> 29 | F45: 50 | G45: 1 | H45: =F45-G45 -> 49 | I45: -
A46: RAJANGAN | B46: PAITON | C46: Ball Goni | E46: =E45+1 -> 30 | F46: 48.6 | G46: 1.1 | H46: =F46-G46 -> 47.5 | I46: -
A47: GRAND TOTAL | E47: =E46 -> 30 | F47: =SUM(F17:F46) -> 1490 | G47: =SUM(G17:G46) -> 34.6 | H47: =SUM(H17:H46) -> 1455.4 | K47: =E7-F47 -> 5
A49: Separation Result :
A50: Product Type | B50: Origin | C50: Pack Type | E50: Product Qty (Kg) | F50: Bits Stem Qty (Kg) | G50: Dust Qty (Kg) | H50: Uncountable Waste Qty (Kg) | I50: TOTAL Qty (Kg)
A51: RAJANGAN | B51: =B46 -> PAITON | C51: Ball Goni | E51: 1186.2 | F51: 228 | G51: 27.9 | H51: =IF(E51="","",(H47-E51-F51-G51)) -> 13.3 | I51: =IF(E51="","",SUM(E51:H51)) -> 1455.4
A52: PERCENTAGE (YIELD) | E52: =IF(E51="","",E51/$H47) -> 0.81503367 | F52: =IF(F51="","",F51/$H47) -> 0.15665796 | G52: =IF(G51="","",G51/$H47) -> 0.019169988 | H52: =IF(H51="","",H51/$H47) -> 0.0091383812 | I52: =IF(I51="","",SUM(E52:H52)) -> 1
A53: Remark :
A54: 1. Gross qty. based on actual weighing during the process.
A55: 2. Tare qty. based on actual weighing during the process.
...

Sheet SPR Batch11
A1: PROCESS CERTIFICATE
A3: DELIVERY NOTE :
A4: Customer | B4: : Bpk. Bimo (PT. Falih Nur Gemilang) | H4: Issued Date : | I4: 46199
A6: Product Type | B6: Origin | C6: Total Pack (Unit) | D6: Pack Type | E6: Gross (Kg) | F6: Tare (Kg) | G6: Netto ( Kg) | H6: Date of Receipt | I6: Delivery Note Number | K6: KT | L6: SLSH
A7: RAJANGAN | B7: PLOSO | C7: 82 | D7: Ball Goni | E7: 3521.4 | F7: 121 | G7: =E7-F7 -> 3400.4 | H7: 46193 | I7: - | K7: 3536.9 | L7: =E7-K7 -> -15.5
A9: Remark :
A10: 1. Gross qty. Based on Delivery Note.
A11: 2. Tare qty. Based on actual weighing during the process.
A13: SEPARATION RESULTS REPORT :
A14: 1. Material Desc : PLOSO
A15: Product Type | B15: Origin | C15: Pack Type | E15: No | F15: Gross (Kg) | G15: Tare (Kg) | H15: Netto ( Kg) | I15: Remark
A16: RAJANGAN | B16: PLOSO | C16: Ball Goni | E16: 1 | F16: 40.2 | G16: 1 | H16: =F16-G16 -> 39.2 | I16: -
A17: RAJANGAN | B17: PLOSO | C17: Ball Goni | E17: =E16+1 -> 2 | F17: 49.2 | G17: 1.4 | H17: =F17-G17 -> 47.8 | I17: -
A18: RAJANGAN | B18: PLOSO | C18: Ball Goni | E18: =E17+1 -> 3 | F18: 41.9 | G18: 1.4 | H18: =F18-G18 -> 40.5 | I18: -
A19: RAJANGAN | B19: PLOSO | C19: Ball Goni | E19: =E18+1 -> 4 | F19: 44.4 | G19: 1.5 | H19: =F19-G19 -> 42.9 | I19: -
A20: RAJANGAN | B20: PLOSO | C20: Ball Goni | E20: =E19+1 -> 5 | F20: 47.6 | G20: 1.5 | H20: =F20-G20 -> 46.1 | I20: -
A21: RAJANGAN | B21: PLOSO | C21: Ball Goni | E21: =E20+1 -> 6 | F21: 42.3 | G21: 1 | H21: =F21-G21 -> 41.3 | I21: -
A22: RAJANGAN | B22: PLOSO | C22: Ball Goni | E22: =E21+1 -> 7 | F22: 53.4 | G22: 1.4 | H22: =F22-G22 -> 52 | I22: -
A23: RAJANGAN | B23: PLOSO | C23: Ball Goni | E23: =E22+1 -> 8 | F23: 40.5 | G23: 1.4 | H23: =F23-G23 -> 39.1 | I23: -
A24: RAJANGAN | B24: PLOSO | C24: Ball Goni | E24: =E23+1 -> 9 | F24: 42.4 | G24: 1.5 | H24: =F24-G24 -> 40.9 | I24: -
A25: RAJANGAN | B25: PLOSO | C25: Ball Goni | E25: =E24+1 -> 10 | F25: 46.3 | G25: 1.5 | H25: =F25-G25 -> 44.8 | I25: -
A26: RAJANGAN | B26: PLOSO | C26: Ball Goni | E26: =E25+1 -> 11 | F26: 30.9 | G26: 1.1 | H26: =F26-G26 -> 29.8 | I26: -
